Workbook

Sheet 第一年
A1: 6000000 | C1: 第一季 | D1: 第二季 | E1: 第三季 | F1: 第四季 | G1: =Q7*3-Q2-Q3 -> 18000000 | H1: 综合费用表 | K1: 利润表 | N1: 资产负债表 | S1: 长短贷
A2: 期初 | B2: 维护 | H2: 管理 | I2: =SUM(C15:F15) -> 400000 | K2: 销售收入 | N2: 现金 | O2: =F48 -> 5600000 | P2: 长贷 | Q2: =SUM(C8:F8,C19:F19) -> 0 | S2: 长贷 | T2: 0.03
B3: 期初现金 | C3: =A1 -> 6000000 | D3: =C48-D2 -> 5900000 | E3: =D48-E2 -> 5800000 | F3: =E48-F2 -> 5700000 | H3: 广告 | I3: =SUM(C24:F24) -> 0 | K3: 直接成本 | L3: =C32+D32+E32+C33+D33+E33+C40+D40+E40+F40 -> 0 | N3: 应收款 | O3: =SUM(G5:G8) -> 0 | P3: 短贷 | Q3: =SUM(C9:F10,C20:F21) -> 0 | S3: 短贷 | T3: 0.07
B4: 裁判融资 | H4: 维护 | I4: =SUM(C2:F2) -> 0 | K4: 毛利 | L4: =L2-L3 -> 0 | N4: 在制品 | P4: 其他应付款 | Q4: =F40 -> 0 | S4: 融资 | T4: 0.04
A5: 财务总监 | B5: 应收款 | H5: 转产 | I5: =SUM(C31:F31) -> 0 | K5: 综合管理费用 | L5: =I17 -> 400000 | N5: 产成品 | P5: 税 | Q5: =L12 -> -100000
B6: 贴现 | C6: =SUM(T13:T16) -> 0 | D6: =SUM(T19:T22) -> 0 | E6: =SUM(T25:T28) -> 0 | F6: =SUM(T31:T34) -> 0 | H6: 市场 | I6: =SUM(C25:F25) -> 0 | K6: 折旧前利润 | L6: =L4-L5 -> -400000 | N6: 原材料 | P6: 负债合计 | Q6: =SUM(Q2:Q5) -> -100000 | S6: 贴现利率
B7: 贴息 | C7: =SUM(U13:U16) -> 0 | D7: =SUM(U19:U22) -> 0 | E7: =SUM(U25:U28) -> 0 | F7: =SUM(U31:U34) -> 0 | H7: 研发 | I7: =SUM(C26:F26) -> 0 | K7: 折旧 | L7: =SUM(C46:F46) -> 0 | N7: 流动资产合计 | O7: =SUM(O2:O6) -> 5600000 | P7: 股东资本 | Q7: =A1 -> 6000000 | S7: 第一季 | T7: 0.02
B8: 长贷 | H8: ISO | I8: =SUM(C27:F27) -> 0 | K8: 息前利润 | L8: =L6-L7 -> -400000 | N8: 机器与设备 | P8: 利润留存 | S8: 第二季 | T8: 0.04
B9: 短贷 | H9: 信息费 | K9: 财务费用 | L9: =SUM(C16:F18,C7:F7) -> 0 | N9: 在建工程 | P9: 年度净利 | Q9: =L13 -> -300000 | S9: 第三季 | T9: 0.07
B10: 融资 | H10: 设计图纸 | I10: =SUM(C35:F35) -> 0 | K10: 营业外支出 | N10: 固定资产合计 | O10: =SUM(O8:O9) -> 0 | P10: 权益 | Q10: =SUM(Q7:Q9) -> 5700000 | S10: 第四季 | T10: 0.09
B11: 还长贷 | H11: 辞退培训 | K11: 税前利润 | L11: =L8-L9-L10 -> -400000 | N11: 合计 | O11: =O10+O7 -> 5600000 | P11: 合计 | Q11: =Q10+Q6 -> 5600000
B12: 还短贷 | H12: 激励 | I12: =SUM(C42:F42) -> 0 | K12: 所得税 | L12: =L11*0.25 -> -100000 | S12: / | T12: 贴现 | U12: 贴息
B13: 还融资 | D13: =C10+C21 -> 0 | E13: =D10+D21 -> 0 | F13: =E10+E21 -> 0 | H13: 人力费 | K13: 净利润 | L13: =L11-L12 -> -300000 | S13: 1.2 | U13: =T13*T7 -> 0
B14: 现金 | C14: =C3+C4+C5+C6-C7+C8+C9+C10-C11-C12-C13 -> 6000000 | D14: =D3+D4+D5+D6-D7+D8+D9+D10-D11-D12-D13 -> 5900000 | E14: =E3+E4+E5+E6-E7+E8+E9+E10-E11-E12-E13 -> 5800000 | F14: =F3+F4+F5+F6-F7+F8+F9+F10-F11-F12-F13 -> 5700000 | H14: 碳中和 | S14: 1.3 | U14: =T14*T8 -> 0
B15: 管理 | C15: 100000 | D15: =C15 -> 100000 | E15: =C15 -> 100000 | F15: =C15 -> 100000 | H15: 特性研发 | I15: =SUM(C34:F34) -> 0 | S15: 1.4 | U15: =T15*T9 -> 0
B16: 长待利息 | D16: =C8*T2+C19*T2 -> 0 | E16: =D16+D8*T2+D19*T2 -> 0 | F16: =E16+E8*T2+E19*T2 -> 0 | H16: 数字化 | I16: =SUM(C28:F28,C38:F38,C44:F44) -> 0 | S16: 2.1 | U16: =T16*T10 -> 0
B17: 短贷利息 | C17: =C12*T3 -> 0 | D17: =D12*T3 -> 0 | E17: =E12*T3 -> 0 | F17: =F12*T3 -> 0 | H17: 合计 | I17: =SUM(I2:I16) -> 400000
B18: 融资利息 | C18: =C13*T4 -> 0 | D18: =D13*T4 -> 0 | E18: =E13*T4 -> 0 | F18: =F13*T4 -> 0 | S18: / | T18: 贴现 | U18: 贴息
B19: 长贷 | C19: =C11 -> 0 | D19: =D11 -> 0 | E19: =E11 -> 0 | F19: =F11 -> 0 | S19: 1.3 | U19: =T19*T7 -> 0
B20: 短贷 | C20: =C12 -> 0 | D20: =D12 -> 0 | E20: =E12 -> 0 | F20: =F12 -> 0 | S20: 1.4 | U20: =T20*T8 -> 0
B21: 融资 | C21: =C13 -> 0 | D21: =D13 -> 0 | E21: =E13 -> 0 | F21: =F13 -> 0 | S21: 2.1 | U21: =T21*T9 -> 0
B22: 违约 | S22: 2.2 | U22: =T22*T10 -> 0
B23: 现金 | C23: =C14-C15-C16-C17-C18+C19+C20+C21 -> 5900000 | D23: =D14-D15-D16-D17-D18+D19+D20+D21 -> 5800000 | E23: =E14-E15-E16-E17-E18+E19+E20+E21 -> 5700000 | F23: =F14-F15-F16-F17-F18+F19+F20+F21 -> 5600000
A24: 营销总监 | B24: 广告 | S24: / | T24: 贴现 | U24: 贴息
B25: 市场 | S25: 1.4 | U25: =T25*T7 -> 0
B26: 产品 | S26: 2.1 | U26: =T26*T8 -> 0
B27: iso | S27: 2.2 | U27: =T27*T9 -> 0
B28: 数字化 | S28: 2.3 | U28: =T28*T10 -> 0
B29: 预算 | C29: =SUM(C24:C28) -> 0 | D29: =SUM(D24:D28) -> 0 | E29: =SUM(E24:E28) -> 0 | F29: =SUM(F24:F28) -> 0
A30: 生产总监 | B30: 建线 | S30: / | T30: 贴现 | U30: 贴息
B31: 转产 | S31: 2.1 | U31: =T31*T7 -> 0
B32: 原料入库 | S32: 2.2 | U32: =T32*T8 -> 0
B33: 计件工资 | S33: 2.3 | U33: =T33*T9 -> 0
B34: 特性 | S34: 2.4 | U34: =T34*T10 -> 0
B35: 设计图纸
B36: 产品零售
B37: 原料出售
B38: 数字化
B39: 预算 | C39: =SUM(C30:C38)-C37-C36 -> 0 | D39: =SUM(D30:D38)-D37-D36 -> 0 | E39: =SUM(E30:E38)-E37-E36 -> 0 | F39: =SUM(F30:F38)-F37-F36 -> 0
A40: 人力资源 | B40: 人员季薪
...

Sheet 第二年
A1: 100000 | C1: 第一季 | D1: 第二季 | E1: 第三季 | F1: 第四季 | G1: =第一年!Q10*3-Q2-Q3 -> 17100000 | H1: 综合费用表 | K1: 利润表 | N1: 资产负债表 | S1: 长短贷
A2: 期初 | B2: 维护 | H2: 管理 | I2: =SUM(C15:F15) -> 400000 | K2: 销售收入 | N2: 现金 | O2: =F48 -> 5300000 | P2: 长贷 | Q2: =SUM(C8:F8,C19:F19)+第一年!Q2 -> 0 | S2: 长贷 | T2: =第一年!T2 -> 0.03
B3: 期初现金 | C3: =第一年!G48-C2 -> 5700000 | D3: =C48-D2 -> 5600000 | E3: =D48-E2 -> 5500000 | F3: =E48-F2 -> 5400000 | H3: 广告 | I3: =SUM(C24:F24) -> 0 | K3: 直接成本 | L3: =C32+D32+E32+C33+D33+E33+C40+D40+E40+F40+第一年!F32+第一年!F33 -> 0 | N3: 应收款 | O3: =SUM(G5:G8) -> 0 | P3: 短贷 | Q3: =SUM(C9:F10,C20:F21) -> 0 | S3: 短贷 | T3: =第一年!T3 -> 0.07
B4: 裁判融资 | H4: 维护 | I4: =SUM(C2:F2) -> 0 | K4: 毛利 | L4: =L2-L3 -> 0 | N4: 在制品 | P4: 其他应付款 | Q4: =F40 -> 0 | S4: 融资 | T4: =第一年!T4 -> 0.04
A5: 财务总监 | B5: 应收款 | H5: 转产 | I5: =SUM(C31:F31) -> 0 | K5: 综合管理费用 | L5: =I17 -> 400000 | N5: 产成品 | P5: 税 | Q5: =L12 -> -100000
B6: 贴现 | C6: =SUM(T13:T16) -> 0 | D6: =SUM(T19:T22) -> 0 | E6: =SUM(T25:T28) -> 0 | F6: =SUM(T31:T34) -> 0 | H6: 市场 | I6: =SUM(C25:F25) -> 0 | K6: 折旧前利润 | L6: =L4-L5 -> -400000 | N6: 原材料 | P6: 负债合计 | Q6: =SUM(Q2:Q5) -> -100000 | S6: 贴现利率
B7: 贴息 | C7: =SUM(U13:U16) -> 0 | D7: =SUM(U19:U22) -> 0 | E7: =SUM(U25:U28) -> 0 | F7: =SUM(U31:U34) -> 0 | H7: 研发 | I7: =SUM(C26:F26) -> 0 | K7: 折旧 | L7: =SUM(C46:F46) -> 0 | N7: 流动资产合计 | O7: =SUM(O2:O6) -> 5300000 | P7: 股东资本 | Q7: =第一年!A1 -> 6000000 | S7: 第一季 | T7: =第一年!T7 -> 0.02
B8: 长贷 | H8: ISO | I8: =SUM(C27:F27) -> 0 | K8: 息前利润 | L8: =L6-L7 -> -400000 | N8: 机器与设备 | P8: 利润留存 | Q8: =第一年!Q10-第一年!Q7 -> -300000 | S8: 第二季 | T8: =第一年!T8 -> 0.04
B9: 短贷 | H9: 信息费 | K9: 财务费用 | L9: =SUM(C16:F18,C7:F7) -> 0 | N9: 在建工程 | P9: 年度净利 | Q9: =L13 -> -300000 | S9: 第三季 | T9: =第一年!T9 -> 0.07
B10: 融资 | H10: 设计图纸 | I10: =SUM(C35:F35) -> 0 | K10: 营业外支出 | N10: 固定资产合计 | O10: =SUM(O8:O9) -> 0 | P10: 权益 | Q10: =SUM(Q7:Q9) -> 5400000 | S10: 第四季 | T10: =第一年!T10 -> 0.09
B11: 还长贷 | H11: 辞退培训 | K11: 税前利润 | L11: =L8-L9-L10 -> -400000 | N11: 合计 | O11: =O10+O7 -> 5300000 | P11: 合计 | Q11: =Q10+Q6 -> 5300000
B12: 还短贷 | C12: =第一年!C9+第一年!C20 -> 0 | D12: =第一年!D9+第一年!D20 -> 0 | E12: =第一年!E9+第一年!E20 -> 0 | F12: =第一年!F9+第一年!F20 -> 0 | H12: 激励 | I12: =SUM(C42:F42) -> 0 | K12: 所得税 | L12: =L11*0.25 -> -100000 | S12: / | T12: 贴现 | U12: 贴息
B13: 还融资 | C13: =第一年!F10+第一年!F21 -> 0 | D13: =C10+C21 -> 0 | E13: =D10+D21 -> 0 | F13: =E10+E21 -> 0 | H13: 人力费 | K13: 净利润 | L13: =L11-L12 -> -300000 | S13: 1.2 | U13: =T13*T7 -> 0
B14: 现金 | C14: =C3+C4+C5+C6-C7+C8+C9+C10-C11-C12-C13 -> 5700000 | D14: =D3+D4+D5+D6-D7+D8+D9+D10-D11-D12-D13 -> 5600000 | E14: =E3+E4+E5+E6-E7+E8+E9+E10-E11-E12-E13 -> 5500000 | F14: =F3+F4+F5+F6-F7+F8+F9+F10-F11-F12-F13 -> 5400000 | H14: 碳中和 | S14: 1.3 | U14: =T14*T8 -> 0
B15: 管理 | C15: =第一年!C15 -> 100000 | D15: =C15 -> 100000 | E15: =C15 -> 100000 | F15: =C15 -> 100000 | H15: 特性研发 | I15: =SUM(C34:F34) -> 0 | S15: 1.4 | U15: =T15*T9 -> 0
B16: 长待利息 | C16: =第一年!F16+第一年!F8*第一年!T2+第一年!F19*第一年!T2 -> 0 | D16: =C8*T2+C19*T2+C16 -> 0 | E16: =D16+D8*T2+D19*T2 -> 0 | F16: =E16+E8*T2+E19*T2 -> 0 | H16: 数字化 | I16: =SUM(C28:F28,C38:F38,C44:F44) -> 0 | S16: 2.1 | U16: =T16*T10 -> 0
B17: 短贷利息 | C17: =C12*T3 -> 0 | D17: =D12*T3 -> 0 | E17: =E12*T3 -> 0 | F17: =F12*T3 -> 0 | H17: 合计 | I17: =SUM(I2:I16) -> 400000
B18: 融资利息 | C18: =C13*T4 -> 0 | D18: =D13*T4 -> 0 | E18: =E13*T4 -> 0 | F18: =F13*T4 -> 0 | S18: / | T18: 贴现 | U18: 贴息
B19: 长贷 | C19: =C11 -> 0 | D19: =D11 -> 0 | E19: =E11 -> 0 | F19: =F11 -> 0 | S19: 1.3 | U19: =T19*T7 -> 0
B20: 短贷 | C20: =C12 -> 0 | D20: =D12 -> 0 | E20: =E12 -> 0 | F20: =F12 -> 0 | S20: 1.4 | U20: =T20*T8 -> 0
B21: 融资 | C21: =C13 -> 0 | D21: =D13 -> 0 | E21: =E13 -> 0 | F21: =F13 -> 0 | S21: 2.1 | U21: =T21*T9 -> 0
B22: 违约 | S22: 2.2 | U22: =T22*T10 -> 0
B23: 现金 | C23: =C14-C15-C16-C17-C18+C19+C20+C21 -> 5600000 | D23: =D14-D15-D16-D17-D18+D19+D20+D21 -> 5500000 | E23: =E14-E15-E16-E17-E18+E19+E20+E21 -> 5400000 | F23: =F14-F15-F16-F17-F18+F19+F20+F21 -> 5300000
A24: 营销总监 | B24: 广告 | S24: / | T24: 贴现 | U24: 贴息
B25: 市场资质 | S25: 1.4 | U25: =T25*T7 -> 0
B26: 产品资质 | S26: 2.1 | U26: =T26*T8 -> 0
B27: iso | S27: 2.2 | U27: =T27*T9 -> 0
B28: 数字化 | S28: 2.3 | U28: =T28*T10 -> 0
B29: 预算 | C29: =SUM(C24:C28) -> 0 | D29: =SUM(D24:D28) -> 0 | E29: =SUM(E24:E28) -> 0 | F29: =SUM(F24:F28) -> 0
A30: 生产总监 | B30: 建线 | S30: / | T30: 贴现 | U30: 贴息
B31: 转产 | S31: 2.1 | U31: =T31*T7 -> 0
B32: 原料入库 | S32: 2.2 | U32: =T32*T8 -> 0
B33: 计件工资 | S33: 2.3 | U33: =T33*T9 -> 0
B34: 特性 | S34: 2.4 | U34: =T34*T10 -> 0
B35: 设计图纸
B36: 产品零售
B37: 原料出售
B38: 数字化
B39: 预算 | C39: =SUM(C30:C38)-C37-C36 -> 0 | D39: =SUM(D30:D38)-D37-D36 -> 0 | E39: =SUM(E30:E38)-E37-E36 -> 0 | F39: =SUM(F30:F38)-F37-F36 -> 0
A40: 人力资源 | B40: 人员季薪
...

Sheet 第三年
A1: 100000 | C1: 第一季 | D1: 第二季 | E1: 第三季 | F1: 第四季 | G1: =第二年!Q10*3-Q2-Q3 -> 16200000 | H1: 综合费用表 | K1: 利润表 | N1: 资产负债表 | S1: 长短贷
A2: 期初 | B2: 维护 | H2: 管理 | I2: =SUM(C15:F15) -> 400000 | K2: 销售收入 | N2: 现金 | O2: =F48 -> 5000000 | P2: 长贷 | Q2: =SUM(C8:F8,C19:F19)+第二年!Q2-C11-D11-E11-F11 -> 0 | S2: 长贷 | T2: =第一年!T2 -> 0.03
B3: 期初现金 | C3: =第二年!G48-C2 -> 5400000 | D3: =C48-D2 -> 5300000 | E3: =D48-E2 -> 5200000 | F3: =E48-F2 -> 5100000 | H3: 广告 | I3: =SUM(C24:F24) -> 0 | K3: 直接成本 | L3: =C32+D32+E32+C33+D33+E33+C40+D40+E40+F40+第二年!F32+第二年!F33 -> 0 | N3: 应收款 | O3: =SUM(G5:G8) -> 0 | P3: 短贷 | Q3: =SUM(C9:F10,C20:F21) -> 0 | S3: 短贷 | T3: =第一年!T3 -> 0.07
B4: 裁判融资 | H4: 维护 | I4: =SUM(C2:F2) -> 0 | K4: 毛利 | L4: =L2-L3 -> 0 | N4: 在制品 | P4: 其他应付款 | Q4: =F40 -> 0 | S4: 融资 | T4: =第一年!T4 -> 0.04
A5: 财务总监 | B5: 应收款 | H5: 转产 | I5: =SUM(C31:F31) -> 0 | K5: 综合管理费用 | L5: =I17 -> 400000 | N5: 产成品 | P5: 税 | Q5: =L12 -> -100000
B6: 贴现 | C6: =SUM(T13:T16) -> 0 | D6: =SUM(T19:T22) -> 0 | E6: =SUM(T25:T28) -> 0 | F6: =SUM(T31:T34) -> 0 | H6: 市场 | I6: =SUM(C25:F25) -> 0 | K6: 折旧前利润 | L6: =L4-L5 -> -400000 | N6: 原材料 | P6: 负债合计 | Q6: =SUM(Q2:Q5) -> -100000 | S6: 贴现利率
B7: 贴息 | C7: =SUM(U13:U16) -> 0 | D7: =SUM(U19:U22) -> 0 | E7: =SUM(U25:U28) -> 0 | F7: =SUM(U31:U34) -> 0 | H7: 研发 | I7: =SUM(C26:F26) -> 0 | K7: 折旧 | L7: =SUM(C46:F46) -> 0 | N7: 流动资产合计 | O7: =SUM(O2:O6) -> 5000000 | P7: 股东资本 | Q7: =第一年!A1 -> 6000000 | S7: 第一季 | T7: =第一年!T7 -> 0.02
B8: 长贷 | H8: ISO | I8: =SUM(C27:F27) -> 0 | K8: 息前利润 | L8: =L6-L7 -> -400000 | N8: 机器与设备 | P8: 利润留存 | Q8: =第二年!Q10-第二年!Q7 -> -600000 | S8: 第二季 | T8: =第一年!T8 -> 0.04
B9: 短贷 | H9: 信息费 | K9: 财务费用 | L9: =SUM(C16:F18,C7:F7) -> 0 | N9: 在建工程 | P9: 年度净利 | Q9: =L13 -> -300000 | S9: 第三季 | T9: =第一年!T9 -> 0.07
B10: 融资 | H10: 设计图纸 | I10: =SUM(C35:F35) -> 0 | K10: 营业外支出 | N10: 固定资产合计 | O10: =SUM(O8:O9) -> 0 | P10: 权益 | Q10: =SUM(Q7:Q9) -> 5100000 | S10: 第四季 | T10: =第一年!T10 -> 0.09
B11: 还长贷 | C11: =第一年!C8+第一年!C19 -> 0 | D11: =第一年!D8+第一年!D19 -> 0 | E11: =第一年!E8+第一年!E19 -> 0 | F11: =第一年!F8+第一年!F19 -> 0 | H11: 辞退培训 | K11: 税前利润 | L11: =L8-L9-L10 -> -400000 | N11: 合计 | O11: =O10+O7 -> 5000000 | P11: 合计 | Q11: =Q10+Q6 -> 5000000
B12: 还短贷 | C12: =第二年!C9+第二年!C20 -> 0 | D12: =第二年!D9+第二年!D20 -> 0 | E12: =第二年!E9+第二年!E20 -> 0 | F12: =第二年!F9+第二年!F20 -> 0 | H12: 激励 | I12: =SUM(C42:F42) -> 0 | K12: 所得税 | L12: =L11*0.25 -> -100000 | S12: / | T12: 贴现 | U12: 贴息
B13: 还融资 | C13: =第二年!F10+第二年!F21 -> 0 | D13: =C10+C21 -> 0 | E13: =D10+D21 -> 0 | F13: =E10+E21 -> 0 | H13: 人力费 | K13: 净利润 | L13: =L11-L12 -> -300000 | S13: 1.2 | U13: =T13*T7 -> 0
B14: 现金 | C14: =C3+C4+C5+C6-C7+C8+C9+C10-C11-C12-C13 -> 5400000 | D14: =D3+D4+D5+D6-D7+D8+D9+D10-D11-D12-D13 -> 5300000 | E14: =E3+E4+E5+E6-E7+E8+E9+E10-E11-E12-E13 -> 5200000 | F14: =F3+F4+F5+F6-F7+F8+F9+F10-F11-F12-F13 -> 5100000 | H14: 碳中和 | S14: 1.3 | U14: =T14*T8 -> 0
B15: 管理 | C15: =第一年!C15 -> 100000 | D15: =C15 -> 100000 | E15: =C15 -> 100000 | F15: =C15 -> 100000 | H15: 特性研发 | I15: =SUM(C34:F34) -> 0 | S15: 1.4 | U15: =T15*T9 -> 0
B16: 长待利息 | C16: =第二年!F16+第二年!F8*第二年!T2+第二年!F19*第二年!T2-C11*T2 -> 0 | D16: =C8*T2+C19*T2+C16-D11*T2 -> 0 | E16: =D16+D8*T2+D19*T2 -> 0 | F16: =E16+E8*T2+E19*T2 -> 0 | H16: 数字化 | I16: =SUM(C28:F28,C38:F38,C44:F44) -> 0 | S16: 2.1 | U16: =T16*T10 -> 0
B17: 短贷利息 | C17: =C12*T3 -> 0 | D17: =D12*T3 -> 0 | E17: =E12*T3 -> 0 | F17: =F12*T3 -> 0 | H17: 合计 | I17: =SUM(I2:I16) -> 400000
B18: 融资利息 | C18: =C13*T4 -> 0 | D18: =D13*T4 -> 0 | E18: =E13*T4 -> 0 | F18: =F13*T4 -> 0 | S18: / | T18: 贴现 | U18: 贴息
B19: 长贷 | C19: =C11 -> 0 | D19: =D11 -> 0 | E19: =E11 -> 0 | F19: =F11 -> 0 | S19: 1.3 | U19: =T19*T7 -> 0
B20: 短贷 | C20: =C12 -> 0 | D20: =D12 -> 0 | E20: =E12 -> 0 | F20: =F12 -> 0 | S20: 1.4 | U20: =T20*T8 -> 0
B21: 融资 | C21: =C13 -> 0 | D21: =D13 -> 0 | E21: =E13 -> 0 | F21: =F13 -> 0 | S21: 2.1 | U21: =T21*T9 -> 0
B22: 违约 | S22: 2.2 | U22: =T22*T10 -> 0
B23: 现金 | C23: =C14-C15-C16-C17-C18+C19+C20+C21 -> 5300000 | D23: =D14-D15-D16-D17-D18+D19+D20+D21 -> 5200000 | E23: =E14-E15-E16-E17-E18+E19+E20+E21 -> 5100000 | F23: =F14-F15-F16-F17-F18+F19+F20+F21 -> 5000000
A24: 营销总监 | B24: 广告 | S24: / | T24: 贴现 | U24: 贴息
B25: 市场资质 | S25: 1.4 | U25: =T25*T7 -> 0
B26: 产品资质 | S26: 2.1 | U26: =T26*T8 -> 0
B27: iso | S27: 2.2 | U27: =T27*T9 -> 0
B28: 数字化 | S28: 2.3 | U28: =T28*T10 -> 0
B29: 预算 | C29: =SUM(C24:C28) -> 0 | D29: =SUM(D24:D28) -> 0 | E29: =SUM(E24:E28) -> 0 | F29: =SUM(F24:F28) -> 0
A30: 生产总监 | B30: 建线 | S30: / | T30: 贴现 | U30: 贴息
B31: 转产 | S31: 2.1 | U31: =T31*T7 -> 0
B32: 原料入库 | S32: 2.2 | U32: =T32*T8 -> 0
B33: 计件工资 | S33: 2.3 | U33: =T33*T9 -> 0
B34: 特性 | S34: 2.4 | U34: =T34*T10 -> 0
B35: 设计图纸
B36: 产品零售
B37: 原料出售
B38: 数字化
B39: 预算 | C39: =SUM(C30:C38)-C37-C36 -> 0 | D39: =SUM(D30:D38)-D37-D36 -> 0 | E39: =SUM(E30:E38)-E37-E36 -> 0 | F39: =SUM(F30:F38)-F37-F36 -> 0
A40: 人力资源 | B40: 人员季薪
...

Sheet 第四年
A1: =第一年!A1 -> 6000000 | C1: 第一季 | D1: 第二季 | E1: 第三季 | F1: 第四季 | G1: =第三年!Q10*3-Q2-Q3 -> 15300000 | H1: 综合费用表 | K1: 利润表 | N1: 资产负债表 | S1: 长短贷
A2: 期初 | B2: 维护 | H2: 管理 | I2: =SUM(C15:F15) -> 400000 | K2: 销售收入 | N2: 现金 | O2: =F48 -> 4700000 | P2: 长贷 | Q2: =SUM(C8:F8,C19:F19)+第三年!Q2-C11-D11-E11-F11 -> 0 | S2: 长贷 | T2: =第一年!T2 -> 0.03
B3: 期初现金 | C3: =第三年!G48-C2 -> 5100000 | D3: =C48-D2 -> 5000000 | E3: =D48-E2 -> 4900000 | F3: =E48-F2 -> 4800000 | H3: 广告 | I3: =SUM(C24:F24) -> 0 | K3: 直接成本 | L3: =C32+C33+D32+D33+E32+E33+第三年!F32+第三年!F33+C40+D40+E40+F40 -> 0 | N3: 应收款 | O3: =SUM(G5:G8) -> 0 | P3: 短贷 | Q3: =SUM(C9:F10,C20:F21) -> 0 | S3: 短贷 | T3: =第一年!T3 -> 0.07
B4: 裁判融资 | H4: 维护 | I4: =SUM(C2:F2) -> 0 | K4: 毛利 | L4: =L2-L3 -> 0 | N4: 在制品 | P4: 其他应付款 | Q4: =F40 -> 0 | S4: 融资 | T4: =第一年!T4 -> 0.04
A5: 财务总监 | B5: 应收款 | H5: 转产 | I5: =SUM(C31:F31) -> 0 | K5: 综合管理费用 | L5: =I17 -> 400000 | N5: 产成品 | P5: 税 | Q5: =L12 -> -100000
B6: 贴现 | C6: =SUM(T13:T16) -> 0 | D6: =SUM(T19:T22) -> 0 | E6: =SUM(T25:T28) -> 0 | F6: =SUM(T31:T34) -> 0 | H6: 市场 | I6: =SUM(C25:F25) -> 0 | K6: 折旧前利润 | L6: =L4-L5 -> -400000 | N6: 原材料 | P6: 负债合计 | Q6: =SUM(Q2:Q5) -> -100000 | S6: 贴现利率
B7: 贴息 | C7: =SUM(U13:U16) -> 0 | D7: =SUM(U19:U22) -> 0 | E7: =SUM(U25:U28) -> 0 | F7: =SUM(U31:U34) -> 0 | H7: 研发 | I7: =SUM(C26:F26) -> 0 | K7: 折旧 | L7: =SUM(C46:F46) -> 0 | N7: 流动资产合计 | O7: =SUM(O2:O6) -> 4700000 | P7: 股东资本 | Q7: =第一年!A1 -> 6000000 | S7: 第一季 | T7: =第一年!T7 -> 0.02
B8: 长贷 | H8: ISO | I8: =SUM(C27:F27) -> 0 | K8: 息前利润 | L8: =L6-L7 -> -400000 | N8: 机器与设备 | P8: 利润留存 | Q8: =第三年!Q10-第三年!Q7 -> -900000 | S8: 第二季 | T8: =第一年!T8 -> 0.04
B9: 短贷 | H9: 信息费 | K9: 财务费用 | L9: =SUM(C16:F18,C7:F7) -> 0 | N9: 在建工程 | P9: 年度净利 | Q9: =L13 -> -300000 | S9: 第三季 | T9: =第一年!T9 -> 0.07
B10: 融资 | H10: 设计图纸 | I10: =SUM(C35:F35) -> 0 | K10: 营业外支出 | N10: 固定资产合计 | O10: =SUM(O8:O9) -> 0 | P10: 权益 | Q10: =SUM(Q7:Q9) -> 4800000 | S10: 第四季 | T10: =第一年!T10 -> 0.09
B11: 还长贷 | C11: =第二年!C8+第二年!C19 -> 0 | D11: =第二年!D8+第二年!D19 -> 0 | E11: =第二年!E8+第二年!E19 -> 0 | F11: =第二年!F8+第二年!F19 -> 0 | H11: 辞退培训 | K11: 税前利润 | L11: =L8-L9-L10 -> -400000 | N11: 合计 | O11: =O10+O7 -> 4700000 | P11: 合计 | Q11: =Q10+Q6 -> 4700000
B12: 还短贷 | C12: =第三年!C9+第三年!C20 -> 0 | D12: =第三年!D9+第三年!D20 -> 0 | E12: =第三年!E9+第三年!E20 -> 0 | F12: =第三年!F9+第三年!F20 -> 0 | H12: 激励 | I12: =SUM(C42:F42) -> 0 | K12: 所得税 | L12: =L11*0.25 -> -100000 | S12: / | T12: 贴现 | U12: 贴息
B13: 还融资 | C13: =第三年!F10+第三年!F21 -> 0 | D13: =C10+C21 -> 0 | E13: =D10+D21 -> 0 | F13: =E10+E21 -> 0 | H13: 人力费 | K13: 净利润 | L13: =L11-L12 -> -300000 | S13: 1.2 | U13: =T13*T7 -> 0
B14: 现金 | C14: =C3+C4+C5+C6-C7+C8+C9+C10-C11-C12-C13 -> 5100000 | D14: =D3+D4+D5+D6-D7+D8+D9+D10-D11-D12-D13 -> 5000000 | E14: =E3+E4+E5+E6-E7+E8+E9+E10-E11-E12-E13 -> 4900000 | F14: =F3+F4+F5+F6-F7+F8+F9+F10-F11-F12-F13 -> 4800000 | H14: 碳中和 | S14: 1.3 | U14: =T14*T8 -> 0
B15: 管理 | C15: =第一年!C15 -> 100000 | D15: =C15 -> 100000 | E15: =C15 -> 100000 | F15: =C15 -> 100000 | H15: 特性研发 | I15: =SUM(C34:F34) -> 0 | S15: 1.4 | U15: =T15*T9 -> 0
B16: 长待利息 | C16: =第三年!F16+第三年!F8*第三年!T2+第三年!F19*第三年!T2-C11*T2 -> 0 | D16: =C8*T2+C19*T2+C16-D11*T2 -> 0 | E16: =D16+D8*T2+D19*T2-D11*T2 -> 0 | F16: =E16+E8*T2+E19*T2-F11*T2 -> 0 | H16: 数字化 | I16: =SUM(C28:F28,C38:F38,C44:F44) -> 0 | S16: 2.1 | U16: =T16*T10 -> 0
B17: 短贷利息 | C17: =C12*T3 -> 0 | D17: =D12*T3 -> 0 | E17: =E12*T3 -> 0 | F17: =F12*T3 -> 0 | H17: 合计 | I17: =SUM(I2:I16) -> 400000
B18: 融资利息 | C18: =C13*T4 -> 0 | D18: =D13*T4 -> 0 | E18: =E13*T4 -> 0 | F18: =F13*T4 -> 0 | S18: / | T18: 贴现 | U18: 贴息
B19: 长贷 | C19: =C11 -> 0 | D19: =D11 -> 0 | E19: =E11 -> 0 | F19: =F11 -> 0 | S19: 1.3 | U19: =T19*T7 -> 0
B20: 短贷 | C20: =C12 -> 0 | D20: =D12 -> 0 | E20: =E12 -> 0 | F20: =F12 -> 0 | S20: 1.4 | U20: =T20*T8 -> 0
B21: 融资 | C21: =C13 -> 0 | D21: =D13 -> 0 | E21: =E13 -> 0 | F21: =F13 -> 0 | S21: 2.1 | U21: =T21*T9 -> 0
B22: 违约 | S22: 2.2 | U22: =T22*T10 -> 0
B23: 现金 | C23: =C14-C15-C16-C17-C18+C19+C20+C21 -> 5000000 | D23: =D14-D15-D16-D17-D18+D19+D20+D21 -> 4900000 | E23: =E14-E15-E16-E17-E18+E19+E20+E21 -> 4800000 | F23: =F14-F15-F16-F17-F18+F19+F20+F21 -> 4700000
A24: 营销总监 | B24: 广告 | S24: / | T24: 贴现 | U24: 贴息
B25: 市场资质 | S25: 1.4 | U25: =T25*T7 -> 0
B26: 产品资质 | S26: 2.1 | U26: =T26*T8 -> 0
B27: iso | S27: 2.2 | U27: =T27*T9 -> 0
B28: 数字化 | S28: 2.3 | U28: =T28*T10 -> 0
B29: 预算 | C29: =SUM(C24:C28) -> 0 | D29: =SUM(D24:D28) -> 0 | E29: =SUM(E24:E28) -> 0 | F29: =SUM(F24:F28) -> 0
A30: 生产总监 | B30: 建线 | S30: / | T30: 贴现 | U30: 贴息
B31: 转产 | S31: 2.1 | U31: =T31*T7 -> 0
B32: 原料入库 | S32: 2.2 | U32: =T32*T8 -> 0
B33: 计件工资 | S33: 2.3 | U33: =T33*T9 -> 0
B34: 特性 | S34: 2.4 | U34: =T34*T10 -> 0
B35: 设计图纸
B36: 产品零售
B37: 原料出售
B38: 数字化
B39: 预算 | C39: =SUM(C30:C38)-C37-C36 -> 0 | D39: =SUM(D30:D38)-D37-D36 -> 0 | E39: =SUM(E30:E38)-E37-E36 -> 0 | F39: =SUM(F30:F38)-F37-F36 -> 0
A40: 人力资源 | B40: 人员季薪
...

Sheet 原材料
C1: 原料成本 | D1: 25 | E1: 25 | F1: 25 | G1: 25 | H1: 25
B2: 产品构成 | C2: R1 | D2: R2 | E2: R3 | F2: R4 | G2: R5 | H2: 直接成本
B3: P1 | C3: 1 | D3: 1 | E3: 1 | F3: 1 | G3: 0 | H3: =C3*$D$1+D3*$E$1+$F$1*E3+$G$1*F3+$H$1*G3 -> 100
B4: P2 | C4: 2 | D4: 2 | E4: 2 | F4: 2 | G4: 0 | H4: =C4*$D$1+D4*$E$1+$F$1*E4+$G$1*F4+$H$1*G4 -> 200
B5: P3 | C5: 4 | D5: 4 | E5: 4 | F5: 4 | G5: 0 | H5: =C5*$D$1+D5*$E$1+$F$1*E5+$G$1*F5+$H$1*G5 -> 400
B6: P4 | C6: 0 | D6: 0 | E6: 0 | F6: 0 | G6: 0 | H6: =C6*$D$1+D6*$E$1+$F$1*E6+$G$1*F6+$H$1*G6 -> 0
B8: R1 | C8: R2 | D8: R3 | E8: R4 | F8: R5 | H8: R1 | I8: R2 | J8: R3 | K8: R4 | L8: R5 | N8: 成本 | P8: P1 | Q8: P2 | R8: P3 | S8: P4 | U8: p1 | V8: p2 | W8: p3 | X8: p4 | Z8: p1 | AA8: p2 | AB8: p3 | AC8: p4
A9: 1n1
A10: 1n2 | H10: =B9+H9-P10-Q10-Q10-R10-R10-R10-R10 -> 0 | I10: =C9+I9-P10-Q10-Q10-R10-R10-R10-R10 -> 0 | J10: =D9+J9-P10-Q10-Q10-R10-R10-R10-R10 -> 0 | K10: =E9+K9-P10-Q10-Q10-R10-R10-R10-R10 -> 0 | N10: =(B9*$D$1+C9*$E$1+D9*$F$1+E9*$G$1+F9*$H$1) -> 0 | U10: =P9+U9-Z10 -> 0 | V10: =Q9+V9-AA10 -> 0 | W10: =R9+W9-AB10 -> 0 | X10: =S9+X9-AC10 -> 0
A11: 1n3 | H11: =B10+H10-P11-Q11-Q11-R11-R11-R11-R11 -> 0 | I11: =C10+I10-P11-Q11-Q11-R11-R11-R11-R11 -> 0 | J11: =D10+J10-P11-Q11-Q11-R11-R11-R11-R11 -> 0 | K11: =E10+K10-P11-Q11-Q11-R11-R11-R11-R11 -> 0 | N11: =(B10*$D$1+C10*$E$1+D10*$F$1+E9*$G$1+F9*$H$1) -> 0 | U11: =P10+U10-Z11 -> 0 | V11: =Q10+V10-AA11 -> 0 | W11: =R10+W10-AB11 -> 0 | X11: =S10+X10-AC11 -> 0
A12: 1n4 | H12: =B11+H11-P12-Q12-Q12-R12-R12-R12-R12 -> 0 | I12: =C11+I11-P12-Q12-Q12-R12-R12-R12-R12 -> 0 | J12: =D11+J11-P12-Q12-Q12-R12-R12-R12-R12 -> 0 | K12: =E11+K11-P12-Q12-Q12-R12-R12-R12-R12 -> 0 | N12: =(B11*$D$1+C11*$E$1+D11*$F$1+E10*$G$1+F10*$H$1) -> 0 | U12: =P11+U11-Z12 -> 0 | V12: =Q11+V11-AA12 -> 0 | W12: =R11+W11-AB12 -> 0 | X12: =S11+X11-AC12 -> 0
A13: 2n1 | H13: =B12+H12-P13-Q13-Q13-R13-R13-R13-R13 -> 0 | I13: =C12+I12-P13-Q13-Q13-R13-R13-R13-R13 -> 0 | J13: =D12+J12-P13-Q13-Q13-R13-R13-R13-R13 -> 0 | K13: =E12+K12-P13-Q13-Q13-R13-R13-R13-R13 -> 0 | N13: =(B12*$D$1+C12*$E$1+D12*$F$1+E11*$G$1+F11*$H$1) -> 0 | U13: =P12+U12-Z13 -> 0 | V13: =Q12+V12-AA13 -> 0 | W13: =R12+W12-AB13 -> 0 | X13: =S12+X12-AC13 -> 0
A14: 2n2 | H14: =B13+H13-P14-Q14-Q14-R14-R14-R14-R14 -> 0 | I14: =C13+I13-P14-Q14-Q14-R14-R14-R14-R14 -> 0 | J14: =D13+J13-P14-Q14-Q14-R14-R14-R14-R14 -> 0 | K14: =E13+K13-P14-Q14-Q14-R14-R14-R14-R14 -> 0 | N14: =(B13*$D$1+C13*$E$1+D13*$F$1+E12*$G$1+F12*$H$1) -> 0 | U14: =P13+U13-Z14 -> 0 | V14: =Q13+V13-AA14 -> 0 | W14: =R13+W13-AB14 -> 0 | X14: =S13+X13-AC14 -> 0
A15: 2n3 | H15: =B14+H14-P15-Q15-Q15-R15-R15-R15-R15 -> 0 | I15: =C14+I14-P15-Q15-Q15-R15-R15-R15-R15 -> 0 | J15: =D14+J14-P15-Q15-Q15-R15-R15-R15-R15 -> 0 | K15: =E14+K14-P15-Q15-Q15-R15-R15-R15-R15 -> 0 | N15: =(B14*$D$1+C14*$E$1+D14*$F$1+E13*$G$1+F13*$H$1) -> 0 | U15: =P14+U14-Z15 -> 0 | V15: =Q14+V14-AA15 -> 0 | W15: =R14+W14-AB15 -> 0 | X15: =S14+X14-AC15 -> 0
A16: 2n4 | H16: =B15+H15-P16-Q16-Q16-R16-R16-R16-R16 -> 0 | I16: =C15+I15-P16-Q16-Q16-R16-R16-R16-R16 -> 0 | J16: =D15+J15-P16-Q16-Q16-R16-R16-R16-R16 -> 0 | K16: =E15+K15-P16-Q16-Q16-R16-R16-R16-R16 -> 0 | N16: =(B15*$D$1+C15*$E$1+D15*$F$1+E14*$G$1+F14*$H$1) -> 0 | U16: =P15+U15-Z16 -> 0 | V16: =Q15+V15-AA16 -> 0 | W16: =R15+W15-AB16 -> 0 | X16: =S15+X15-AC16 -> 0
A17: 3n1 | H17: =B16+H16-P17-Q17-Q17-R17-R17-R17-R17 -> 0 | I17: =C16+I16-P17-Q17-Q17-R17-R17-R17-R17 -> 0 | J17: =D16+J16-P17-Q17-Q17-R17-R17-R17-R17 -> 0 | K17: =E16+K16-P17-Q17-Q17-R17-R17-R17-R17 -> 0 | N17: =(B16*$D$1+C16*$E$1+D16*$F$1+E15*$G$1+F15*$H$1) -> 0 | U17: =P16+U16-Z17 -> 0 | V17: =Q16+V16-AA17 -> 0 | W17: =R16+W16-AB17 -> 0 | X17: =S16+X16-AC17 -> 0
A18: 3n2 | H18: =B17+H17-P18-Q18-Q18-R18-R18-R18-R18 -> 0 | I18: =C17+I17-P18-Q18-Q18-R18-R18-R18-R18 -> 0 | J18: =D17+J17-P18-Q18-Q18-R18-R18-R18-R18 -> 0 | K18: =E17+K17-P18-Q18-Q18-R18-R18-R18-R18 -> 0 | N18: =(B17*$D$1+C17*$E$1+D17*$F$1+E16*$G$1+F16*$H$1) -> 0 | U18: =P17+U17-Z18 -> 0 | V18: =Q17+V17-AA18 -> 0 | W18: =R17+W17-AB18 -> 0 | X18: =S17+X17-AC18 -> 0
A19: 3n3 | H19: =B18+H18-P19-Q19-Q19-R19-R19-R19-R19 -> 0 | I19: =C18+I18-P19-Q19-Q19-R19-R19-R19-R19 -> 0 | J19: =D18+J18-P19-Q19-Q19-R19-R19-R19-R19 -> 0 | K19: =E18+K18-P19-Q19-Q19-R19-R19-R19-R19 -> 0 | N19: =(B18*$D$1+C18*$E$1+D18*$F$1+E17*$G$1+F17*$H$1) -> 0 | U19: =P18+U18-Z19 -> 0 | V19: =Q18+V18-AA19 -> 0 | W19: =R18+W18-AB19 -> 0 | X19: =S18+X18-AC19 -> 0
A20: 3n4 | H20: =B19+H19-P20-Q20-Q20-R20-R20-R20-R20 -> 0 | I20: =C19+I19-P20-Q20-Q20-R20-R20-R20-R20 -> 0 | J20: =D19+J19-P20-Q20-Q20-R20-R20-R20-R20 -> 0 | K20: =E19+K19-P20-Q20-Q20-R20-R20-R20-R20 -> 0 | N20: =(B19*$D$1+C19*$E$1+D19*$F$1+E18*$G$1+F18*$H$1) -> 0 | U20: =P19+U19-Z20 -> 0 | V20: =Q19+V19-AA20 -> 0 | W20: =R19+W19-AB20 -> 0 | X20: =S19+X19-AC20 -> 0
A21: 4n1 | H21: =B20+H20-P21-Q21-Q21-R21-R21-R21-R21 -> 0 | I21: =C20+I20-P21-Q21-Q21-R21-R21-R21-R21 -> 0 | J21: =D20+J20-P21-Q21-Q21-R21-R21-R21-R21 -> 0 | K21: =E20+K20-P21-Q21-Q21-R21-R21-R21-R21 -> 0 | N21: =(B20*$D$1+C20*$E$1+D20*$F$1+E19*$G$1+F19*$H$1) -> 0 | U21: =P20+U20-Z21 -> 0 | V21: =Q20+V20-AA21 -> 0 | W21: =R20+W20-AB21 -> 0 | X21: =S20+X20-AC21 -> 0
A22: 4n2 | H22: =B21+H21-P22-Q22-Q22-R22-R22-R22-R22 -> 0 | I22: =C21+I21-P22-Q22-Q22-R22-R22-R22-R22 -> 0 | J22: =D21+J21-P22-Q22-Q22-R22-R22-R22-R22 -> 0 | K22: =E21+K21-P22-Q22-Q22-R22-R22-R22-R22 -> 0 | N22: =(B21*$D$1+C21*$E$1+D21*$F$1+E20*$G$1+F20*$H$1) -> 0 | U22: =P21+U21-Z22 -> 0 | V22: =Q21+V21-AA22 -> 0 | W22: =R21+W21-AB22 -> 0 | X22: =S21+X21-AC22 -> 0
... A24: 4n4 | H24: =B23+H23-P24-Q24-Q24-R24-R24-R24-R24 -> 0 | I24: =C23+I23-P24-Q24-Q24-R24-R24-R24-R24 -> 0 | J24: =D23+J23-P24-Q24-Q24-R24-R24-R24-R24 -> 0 | K24: =E23+K23-P24-Q24-Q24-R24-R24-R24-R24 -> 0 | N24: =(B23*$D$1+C23*$E$1+D23*$F$1+E22*$G$1+F22*$H$1) -> 0 | U24: =P23+U23-Z24 -> 0 | V24: =Q23+V23-AA24 -> 0 | W24: =R23+W23-AB24 -> 0 | X24: =S23+X23-AC24 -> 0
B26: 线 | C26: 基础产能 | D26: 初级工人 | H26: 高级工人 | J26: 工时 （下拉） | K26: 班次 | M26: 产能 | N26: 制造费用 | O26: 传统线 | P26: 15 | Z26: 一年 | AA26: 两年 | AB26: 三年 | AC26: 四年 | AF26: 效率 | AG26: 需要激励
D27: 效率 | E27: 效率 | F27: 效率 | H27: 效率 | I27: 效率 | R27: 初级 | S27: 高级 | Z27: 辞退福利 | AF27: 0.5 | AG27: =(1-AF27)*ROUNDUP(100/$AH$27,0)*100 -> 6250 | AH27: 0.8
A28: 1 | C28: 80 | D28: 0.5 | H28: 1 | J28: 8 | K28: =IF(J28=8,1,1.2) -> 1 | M28: =INT(C28*(1+(D28+E28+F28)/4+H28+I28))*K28 -> 170 | N28: =M28*$P$26 -> 2550 | O28: 自动线 | P28: 15 | S28: 2520 | Z28: =2*R28 -> 0 | AA28: =3*R28 -> 0 | AB28: =4*R28 -> 0 | AC28: =4*R28 -> 0 | AF28: 0.9 | AG28: =(1-AF28)*ROUNDUP(100/$C$3,0)*100 -> 1000
A29: 2 | C29: 80 | D29: 0.5 | H29: 1 | J29: 8 | K29: =IF(J29=8,1,1.2) -> 1 | M29: =INT(C29*(1+(D29+E29+F29)/4+H29+I29))*K29 -> 170 | N29: =M29*$P$26 -> 2550 | Z29: 9686 | AF29: 0.7 | AG29: =(1-AF29)*ROUNDUP(100/$C$3,0)*100 -> 3000
A30: 3 | C30: 80 | D30: 0.5 | H30: 1 | J30: 8 | K30: =IF(J30=8,1,1.2) -> 1 | M30: =INT(C30*(1+(D30+E30+F30)/4+H30+I30))*K30 -> 170 | N30: =M30*$P$26 -> 2550 | O30: 智能线 | P30: 10 | Z30: 9352 | AG30: =(1-AF30)*ROUNDUP(100/$C$3,0)*100 -> 10000
A31: 4 | C31: 80 | D31: 0.5 | H31: 1 | J31: 8 | K31: =IF(J31=8,1,1.2) -> 1 | M31: =INT(C31*(1+(D31+E31+F31)/4+H31+I31))*K31 -> 170 | N31: =M31*$P$26 -> 2550
A32: 5 | C32: 80 | D32: 0.5 | H32: 1 | J32: 8 | K32: =IF(J32=8,1,1.2) -> 1 | M32: =INT(C32*(1+(D32+E32+F32)/4+H32+I32))*K32 -> 170 | N32: =M32*$P$26 -> 2550
A33: 6 | C33: 80 | D33: 0.5 | H33: 1 | J33: 8 | K33: =IF(J33=8,1,1.2) -> 1 | M33: =INT(C33*(1+(D33+E33+F33)/4+H33+I33))*K33 -> 170 | N33: =M33*$P$26 -> 2550
A34: 7 | C34: 80 | D34: 0.5 | H34: 1 | J34: 8 | K34: =IF(J34=8,1,1.2) -> 1 | M34: =INT(C34*(1+(D34+E34+F34)/4+H34+I34))*K34 -> 170 | N34: =M34*$P$26 -> 2550
A35: 8 | C35: 80 | D35: 0.5 | H35: 1 | J35: 8 | K35: =IF(J35=8,1,1.2) -> 1 | M35: =INT(C35*(1+(D35+E35+F35)/4+H35+I35))*K35 -> 170 | N35: =M35*$P$26 -> 2550
A36: 9 | C36: 80 | D36: 0.5 | H36: 1 | J36: 8 | K36: =IF(J36=8,1,1.2) -> 1 | M36: =INT(C36*(1+(D36+E36+F36)/4+H36+I36))*K36 -> 170 | N36: =M36*$P$26 -> 2550
A37: 10 | C37: 80 | D37: 0.5 | H37: 1 | J37: 8 | K37: =IF(J37=8,1,1.2) -> 1 | M37: =INT(C37*(1+(D37+E37+F37)/4+H37+I37))*K37 -> 170 | N37: =M37*$P$26 -> 2550
A38: 11 | C38: 80 | D38: 0.5 | H38: 1 | J38: 8 | K38: =IF(J38=8,1,1.2) -> 1 | M38: =INT(C38*(1+(D38+E38+F38)/4+H38+I38))*K38 -> 170 | N38: =M38*$P$26 -> 2550
A39: 12 | C39: 80 | D39: 0.5 | H39: 1 | J39: 8 | K39: =IF(J39=8,1,1.2) -> 1 | M39: =INT(C39*(1+(D39+E39+F39)/4+H39+I39))*K39 -> 170 | N39: =M39*$P$26 -> 2550
A40: 13 | C40: 80 | D40: 0.5 | H40: 1 | J40: 8 | K40: =IF(J40=8,1,1.2) -> 1 | M40: =INT(C40*(1+(D40+E40+F40)/4+H40+I40))*K40 -> 170 | N40: =M40*$P$26 -> 2550
A41: 14 | C41: 80 | D41: 0.5 | H41: 1 | J41: 8 | K41: =IF(J41=8,1,1.2) -> 1 | M41: =INT(C41*(1+(D41+E41+F41)/4+H41+I41))*K41 -> 170 | N41: =M41*$P$26 -> 2550
A42: 15 | C42: 80 | D42: 0.5 | H42: 1 | J42: 8 | K42: =IF(J42=8,1,1.2) -> 1 | M42: =INT(C42*(1+(D42+E42+F42)/4+H42+I42))*K42 -> 170 | N42: =M42*$P$26 -> 2550 | U42: 总工资
A43: 16 | C43: 80 | D43: 0.5 | H43: 1 | J43: 8 | K43: =IF(J43=8,1,1.2) -> 1 | M43: =INT(C43*(1+(D43+E43+F43)/4+H43+I43))*K43 -> 170 | N43: =M43*$P$26 -> 2550 | U43: =SUM(R28:S43)*3 -> 7560
...
